DISPLAY "(null)" invalid; disabling X11 forwarding
I tensorflow/stream_executor/dso_loader.cc:108] successfully opened CUDA library libcublas.so locally
I tensorflow/stream_executor/dso_loader.cc:108] successfully opened CUDA library libcudnn.so locally
I tensorflow/stream_executor/dso_loader.cc:108] successfully opened CUDA library libcufft.so locally
I tensorflow/stream_executor/dso_loader.cc:108] successfully opened CUDA library libcuda.so locally
I tensorflow/stream_executor/dso_loader.cc:108] successfully opened CUDA library libcurand.so locally
INFO:tensorflow:PS hosts are: ['raiders1:2200']
INFO:tensorflow:Worker hosts are: ['raiders1:2201', 'raiders1:2202', 'raiders1:2203', 'raiders1:2204', 'raiders2:2205', 'raiders2:2206', 'raiders2:2207', 'raiders2:2208', 'raiders3:2209', 'raiders3:2210', 'raiders3:2211', 'raiders3:2212', 'raiders8:2213', 'raiders8:2214', 'raiders8:2215', 'raiders8:2216']
E tensorflow/stream_executor/cuda/cuda_driver.cc:491] failed call to cuInit: CUDA_ERROR_NO_DEVICE
I tensorflow/stream_executor/cuda/cuda_diagnostics.cc:153] retrieving CUDA diagnostic information for host: raiders2
I tensorflow/stream_executor/cuda/cuda_diagnostics.cc:160] hostname: raiders2
I tensorflow/stream_executor/cuda/cuda_diagnostics.cc:185] libcuda reported version is: Not found: was unable to find libcuda.so DSO loaded into this program
I tensorflow/stream_executor/cuda/cuda_diagnostics.cc:347] driver version file contents: """NVRM version: NVIDIA UNIX x86_64 Kernel Module  352.93  Tue Apr  5 18:18:24 PDT 2016
GCC version:  gcc version 4.8.4 (Ubuntu 4.8.4-2ubuntu1~14.04.1) 
"""
I tensorflow/stream_executor/cuda/cuda_diagnostics.cc:189] kernel reported version is: 352.93.0
I tensorflow/core/common_runtime/gpu/gpu_init.cc:81] No GPU devices available on machine.
I tensorflow/core/distributed_runtime/rpc/grpc_channel.cc:206] Initialize HostPortsGrpcChannelCache for job ps -> {raiders1:2200}
I tensorflow/core/distributed_runtime/rpc/grpc_channel.cc:206] Initialize HostPortsGrpcChannelCache for job worker -> {raiders1:2201, raiders1:2202, raiders1:2203, raiders1:2204, raiders2:2205, raiders2:2206, localhost:2207, raiders2:2208, raiders3:2209, raiders3:2210, raiders3:2211, raiders3:2212, raiders8:2213, raiders8:2214, raiders8:2215, raiders8:2216}
I tensorflow/core/distributed_runtime/rpc/grpc_server_lib.cc:202] Started server with target: grpc://localhost:2207
INFO:tensorflow:Learning rate: 0.005000, momentum: 0.300000
INFO:tensorflow:Sync mode!!!!!!
INFO:tensorflow:Compute groups : 4
INFO:tensorflow:SyncReplicas enabled: replicas_to_aggregate=16; total_num_replicas=16
INFO:tensorflow:Num nodes per compute groups: 4
INFO:tensorflow:Tokens per step: 4
INFO:tensorflow:2016-07-26 06:06:04.174813 Supervisor
INFO:tensorflow:got sessions! 2016-07-26 06:06:19.486874 
INFO:tensorflow:Started 3 queues for processing input data.
INFO:tensorflow:Step: 399, Loss: 5.428179, time: 33.331 sec/batch
INFO:tensorflow:Step: 399, Loss: 5.781181, time: 14.851 sec/batch
INFO:tensorflow:Step: 403, Loss: 5.237729, time: 10.170 sec/batch
INFO:tensorflow:Step: 407, Loss: 6.151316, time: 14.939 sec/batch
INFO:tensorflow:Step: 410, Loss: 5.446485, time: 18.025 sec/batch
INFO:tensorflow:Step: 414, Loss: 5.324257, time: 17.918 sec/batch
INFO:tensorflow:Step: 420, Loss: 5.873232, time: 16.034 sec/batch
INFO:tensorflow:Step: 424, Loss: 5.556843, time: 14.603 sec/batch
INFO:tensorflow:Step: 427, Loss: 5.368652, time: 15.866 sec/batch
INFO:tensorflow:Step: 432, Loss: 5.311195, time: 16.909 sec/batch
INFO:tensorflow:Step: 437, Loss: 6.776084, time: 15.296 sec/batch
INFO:tensorflow:Step: 441, Loss: 5.491526, time: 16.034 sec/batch
INFO:tensorflow:Step: 446, Loss: 5.466418, time: 20.817 sec/batch
INFO:tensorflow:Step: 452, Loss: 5.213414, time: 25.831 sec/batch
INFO:tensorflow:Step: 458, Loss: 5.749625, time: 16.418 sec/batch
INFO:tensorflow:Step: 463, Loss: 5.023409, time: 23.318 sec/batch
INFO:tensorflow:Step: 469, Loss: 5.461696, time: 22.332 sec/batch
INFO:tensorflow:Step: 475, Loss: 5.027457, time: 22.291 sec/batch
INFO:tensorflow:Step: 482, Loss: 4.983270, time: 19.026 sec/batch
INFO:tensorflow:Step: 486, Loss: 5.060437, time: 31.899 sec/batch
INFO:tensorflow:Step: 493, Loss: 5.198839, time: 24.238 sec/batch
INFO:tensorflow:Step: 499, Loss: 4.900229, time: 27.708 sec/batch
INFO:tensorflow:Step: 506, Loss: 5.321607, time: 44.052 sec/batch
INFO:tensorflow:Step: 514, Loss: 5.399368, time: 39.354 sec/batch
INFO:tensorflow:Step: 520, Loss: 5.306122, time: 36.745 sec/batch
INFO:tensorflow:Step: 524, Loss: 5.279345, time: 38.858 sec/batch
INFO:tensorflow:Step: 528, Loss: 5.119789, time: 29.537 sec/batch
INFO:tensorflow:Step: 532, Loss: 5.416952, time: 21.691 sec/batch
INFO:tensorflow:Step: 536, Loss: 5.458865, time: 21.752 sec/batch
INFO:tensorflow:Step: 540, Loss: 5.599622, time: 20.851 sec/batch
INFO:tensorflow:Step: 544, Loss: 5.130866, time: 24.621 sec/batch
INFO:tensorflow:Step: 548, Loss: 5.487744, time: 32.195 sec/batch
INFO:tensorflow:Step: 552, Loss: 5.721783, time: 25.403 sec/batch
INFO:tensorflow:Step: 556, Loss: 5.124327, time: 30.026 sec/batch
INFO:tensorflow:Step: 560, Loss: 5.302210, time: 26.011 sec/batch
INFO:tensorflow:Step: 564, Loss: 5.138829, time: 38.336 sec/batch
INFO:tensorflow:Step: 568, Loss: 5.937762, time: 25.423 sec/batch
INFO:tensorflow:Step: 571, Loss: 5.251810, time: 25.044 sec/batch
INFO:tensorflow:Step: 576, Loss: 4.916357, time: 33.161 sec/batch
INFO:tensorflow:Step: 580, Loss: 5.529548, time: 30.466 sec/batch
INFO:tensorflow:Step: 584, Loss: 5.235670, time: 26.529 sec/batch
INFO:tensorflow:Step: 588, Loss: 5.076204, time: 30.849 sec/batch
INFO:tensorflow:Step: 592, Loss: 5.325745, time: 29.922 sec/batch
Traceback (most recent call last):
  File "/afs/cs.stanford.edu/u/daniter/tf-test/inception/bazel-bin/inception/imagenet_distributed_train.runfiles/__main__/inception/imagenet_distributed_train.py", line 69, in <module>
    tf.app.run()
  File "/usr/local/lib/python2.7/dist-packages/tensorflow/python/platform/app.py", line 30, in run
    sys.exit(main(sys.argv))
  File "/afs/cs.stanford.edu/u/daniter/tf-test/inception/bazel-bin/inception/imagenet_distributed_train.runfiles/__main__/inception/imagenet_distributed_train.py", line 65, in main
    inception_distributed_train.train(server.target, dataset, cluster_spec)
  File "/afs/cs.stanford.edu/u/daniter/tf-test/inception/bazel-bin/inception/imagenet_distributed_train.runfiles/__main__/inception/inception_distributed_train.py", line 329, in train
    loss_value, step = sess.run([train_op, global_step])
  File "/usr/local/lib/python2.7/dist-packages/tensorflow/python/client/session.py", line 372, in run
    run_metadata_ptr)
  File "/usr/local/lib/python2.7/dist-packages/tensorflow/python/client/session.py", line 636, in _run
    feed_dict_string, options, run_metadata)
  File "/usr/local/lib/python2.7/dist-packages/tensorflow/python/client/session.py", line 708, in _do_run
    target_list, options, run_metadata)
  File "/usr/local/lib/python2.7/dist-packages/tensorflow/python/client/session.py", line 728, in _do_call
    raise type(e)(node_def, op, message)
tensorflow.python.framework.errors.UnavailableError
